[2025-02-23T14:06:35.091+0000] {local_task_job_runner.py:123} INFO - ::group::Pre task execution logs
[2025-02-23T14:06:35.097+0000] {taskinstance.py:2613} INFO - Dependencies all met for dep_context=non-requeueable deps ti=<TaskInstance: etl_climate.extract_data scheduled__2025-02-22T00:00:00+00:00 [queued]>
[2025-02-23T14:06:35.101+0000] {taskinstance.py:2613} INFO - Dependencies all met for dep_context=requeueable deps ti=<TaskInstance: etl_climate.extract_data scheduled__2025-02-22T00:00:00+00:00 [queued]>
[2025-02-23T14:06:35.101+0000] {taskinstance.py:2866} INFO - Starting attempt 2 of 2
[2025-02-23T14:06:35.110+0000] {taskinstance.py:2889} INFO - Executing <Task(DockerOperator): extract_data> on 2025-02-22 00:00:00+00:00
[2025-02-23T14:06:35.111+0000] {standard_task_runner.py:72} INFO - Started process 105 to run task
[2025-02-23T14:06:35.113+0000] {standard_task_runner.py:104} INFO - Running: ['airflow', 'tasks', 'run', 'etl_climate', 'extract_data', 'scheduled__2025-02-22T00:00:00+00:00', '--job-id', '69', '--raw', '--subdir', 'DAGS_FOLDER/climate_extract_dag.py', '--cfg-path', '/tmp/tmpx53oc958']
[2025-02-23T14:06:35.115+0000] {standard_task_runner.py:105} INFO - Job 69: Subtask extract_data
[2025-02-23T14:06:35.140+0000] {task_command.py:467} INFO - Running <TaskInstance: etl_climate.extract_data scheduled__2025-02-22T00:00:00+00:00 [running]> on host a5a513c5bb31
[2025-02-23T14:06:35.176+0000] {taskinstance.py:3132} INFO - Exporting env vars: AIRFLOW_CTX_DAG_OWNER='airflow' AIRFLOW_CTX_DAG_ID='etl_climate' AIRFLOW_CTX_TASK_ID='extract_data' AIRFLOW_CTX_EXECUTION_DATE='2025-02-22T00:00:00+00:00' AIRFLOW_CTX_TRY_NUMBER='2' AIRFLOW_CTX_DAG_RUN_ID='scheduled__2025-02-22T00:00:00+00:00'
[2025-02-23T14:06:35.177+0000] {taskinstance.py:731} INFO - ::endgroup::
[2025-02-23T14:06:35.200+0000] {docker.py:379} INFO - Starting docker container from image dbt_docker_image
[2025-02-23T14:06:37.487+0000] {docker.py:73} INFO - [0m14:06:37  Running with dbt=1.9.2
[2025-02-23T14:06:37.679+0000] {docker.py:73} INFO - [0m14:06:37  Registered adapter: duckdb=1.9.1
[2025-02-23T14:06:37.731+0000] {docker.py:73} INFO - [0m14:06:37  Unable to do partial parsing because saved manifest not found. Starting full parse.
[2025-02-23T14:06:38.785+0000] {docker.py:73} INFO - [0m14:06:38  Found 1 model, 1 seed, 19 data tests, 424 macros
[2025-02-23T14:06:38.787+0000] {docker.py:73} INFO - [0m14:06:38
[2025-02-23T14:06:38.787+0000] {docker.py:73} INFO - [0m14:06:38  Concurrency: 1 threads (target='dev')
[2025-02-23T14:06:38.787+0000] {docker.py:73} INFO - [0m14:06:38
[2025-02-23T14:06:40.230+0000] {docker.py:73} INFO - [0m14:06:40  1 of 1 START sql table model main.open_meteo_raw_data .......................... [RUN]
[2025-02-23T14:07:06.861+0000] {docker.py:73} INFO - [0m14:07:06  1 of 1 ERROR creating sql table model main.open_meteo_raw_data ................. [[31mERROR[0m in 26.63s]
[2025-02-23T14:07:06.899+0000] {docker.py:73} INFO - [0m14:07:06
[2025-02-23T14:07:06.899+0000] {docker.py:73} INFO - [0m14:07:06  Finished running 1 table model in 0 hours 0 minutes and 28.11 seconds (28.11s).
[2025-02-23T14:07:06.922+0000] {docker.py:73} INFO - [0m14:07:06
[2025-02-23T14:07:06.923+0000] {docker.py:73} INFO - [0m14:07:06  [31mCompleted with 1 error, 0 partial successes, and 0 warnings:[0m
[2025-02-23T14:07:06.923+0000] {docker.py:73} INFO - [0m14:07:06
[2025-02-23T14:07:06.924+0000] {docker.py:73} INFO - [0m14:07:06    Runtime Error in model open_meteo_raw_data (models/open_meteo_raw_data.sql)
[2025-02-23T14:07:06.924+0000] {docker.py:73} INFO -   TransactionContext Error: Failed to commit: PRIMARY KEY or UNIQUE constraint violation: duplicate key "2025-02-21 20:00:00, nan, nan"
[2025-02-23T14:07:06.924+0000] {docker.py:73} INFO - [0m14:07:06
[2025-02-23T14:07:06.925+0000] {docker.py:73} INFO - [0m14:07:06  Done. PASS=0 WARN=0 ERROR=1 SKIP=0 TOTAL=1
[2025-02-23T14:07:07.495+0000] {taskinstance.py:3311} ERROR - Task failed with exception
Traceback (most recent call last):
  File "/home/airflow/.local/lib/python3.12/site-packages/airflow/models/taskinstance.py", line 767, in _execute_task
    result = _execute_callable(context=context, **execute_callable_kwargs)
             ^^^^^^^^^^^^^^^^^^^^^^^^^^^^^^^^^^^^^^^^^^^^^^^^^^^^^^^^^^^^^
  File "/home/airflow/.local/lib/python3.12/site-packages/airflow/models/taskinstance.py", line 733, in _execute_callable
    return ExecutionCallableRunner(
           ^^^^^^^^^^^^^^^^^^^^^^^^
  File "/home/airflow/.local/lib/python3.12/site-packages/airflow/utils/operator_helpers.py", line 252, in run
    return self.func(*args, **kwargs)
           ^^^^^^^^^^^^^^^^^^^^^^^^^^
  File "/home/airflow/.local/lib/python3.12/site-packages/airflow/models/baseoperator.py", line 422, in wrapper
    return func(self, *args, **kwargs)
           ^^^^^^^^^^^^^^^^^^^^^^^^^^^
  File "/home/airflow/.local/lib/python3.12/site-packages/airflow/providers/docker/operators/docker.py", line 519, in execute
    return self._run_image()
           ^^^^^^^^^^^^^^^^^
  File "/home/airflow/.local/lib/python3.12/site-packages/airflow/providers/docker/operators/docker.py", line 396, in _run_image
    return self._run_image_with_mounts(self.mounts, add_tmp_variable=False)
           ^^^^^^^^^^^^^^^^^^^^^^^^^^^^^^^^^^^^^^^^^^^^^^^^^^^^^^^^^^^^^^^^
  File "/home/airflow/.local/lib/python3.12/site-packages/airflow/providers/docker/operators/docker.py", line 453, in _run_image_with_mounts
    raise DockerContainerFailedException(f"Docker container failed: {result!r}", logs=log_lines)
airflow.providers.docker.exceptions.DockerContainerFailedException: Docker container failed: {'StatusCode': 1}
[2025-02-23T14:07:07.498+0000] {taskinstance.py:1225} INFO - Marking task as FAILED. dag_id=etl_climate, task_id=extract_data, run_id=scheduled__2025-02-22T00:00:00+00:00, execution_date=20250222T000000, start_date=20250223T140635, end_date=20250223T140707
[2025-02-23T14:07:07.505+0000] {taskinstance.py:340} INFO - ::group::Post task execution logs
[2025-02-23T14:07:07.505+0000] {standard_task_runner.py:124} ERROR - Failed to execute job 69 for task extract_data (Docker container failed: {'StatusCode': 1}; 105)
Traceback (most recent call last):
  File "/home/airflow/.local/lib/python3.12/site-packages/airflow/task/task_runner/standard_task_runner.py", line 117, in _start_by_fork
    ret = args.func(args, dag=self.dag)
          ^^^^^^^^^^^^^^^^^^^^^^^^^^^^^
  File "/home/airflow/.local/lib/python3.12/site-packages/airflow/cli/cli_config.py", line 49, in command
    return func(*args, **kwargs)
           ^^^^^^^^^^^^^^^^^^^^^
  File "/home/airflow/.local/lib/python3.12/site-packages/airflow/utils/cli.py", line 116, in wrapper
    return f(*args, **kwargs)
           ^^^^^^^^^^^^^^^^^^
  File "/home/airflow/.local/lib/python3.12/site-packages/airflow/cli/commands/task_command.py", line 483, in task_run
    task_return_code = _run_task_by_selected_method(args, _dag, ti)
                       ^^^^^^^^^^^^^^^^^^^^^^^^^^^^^^^^^^^^^^^^^^^^
  File "/home/airflow/.local/lib/python3.12/site-packages/airflow/cli/commands/task_command.py", line 256, in _run_task_by_selected_method
    return _run_raw_task(args, ti)
           ^^^^^^^^^^^^^^^^^^^^^^^
  File "/home/airflow/.local/lib/python3.12/site-packages/airflow/cli/commands/task_command.py", line 341, in _run_raw_task
    return ti._run_raw_task(
           ^^^^^^^^^^^^^^^^^
  File "/home/airflow/.local/lib/python3.12/site-packages/airflow/utils/session.py", line 97, in wrapper
    return func(*args, session=session, **kwargs)
           ^^^^^^^^^^^^^^^^^^^^^^^^^^^^^^^^^^^^^^
  File "/home/airflow/.local/lib/python3.12/site-packages/airflow/models/taskinstance.py", line 3005, in _run_raw_task
    return _run_raw_task(
           ^^^^^^^^^^^^^^
  File "/home/airflow/.local/lib/python3.12/site-packages/airflow/models/taskinstance.py", line 273, in _run_raw_task
    TaskInstance._execute_task_with_callbacks(
  File "/home/airflow/.local/lib/python3.12/site-packages/airflow/models/taskinstance.py", line 3159, in _execute_task_with_callbacks
    result = self._execute_task(context, task_orig)
             ^^^^^^^^^^^^^^^^^^^^^^^^^^^^^^^^^^^^^^
  File "/home/airflow/.local/lib/python3.12/site-packages/airflow/models/taskinstance.py", line 3183, in _execute_task
    return _execute_task(self, context, task_orig)
           ^^^^^^^^^^^^^^^^^^^^^^^^^^^^^^^^^^^^^^^
  File "/home/airflow/.local/lib/python3.12/site-packages/airflow/models/taskinstance.py", line 767, in _execute_task
    result = _execute_callable(context=context, **execute_callable_kwargs)
             ^^^^^^^^^^^^^^^^^^^^^^^^^^^^^^^^^^^^^^^^^^^^^^^^^^^^^^^^^^^^^
  File "/home/airflow/.local/lib/python3.12/site-packages/airflow/models/taskinstance.py", line 733, in _execute_callable
    return ExecutionCallableRunner(
           ^^^^^^^^^^^^^^^^^^^^^^^^
  File "/home/airflow/.local/lib/python3.12/site-packages/airflow/utils/operator_helpers.py", line 252, in run
    return self.func(*args, **kwargs)
           ^^^^^^^^^^^^^^^^^^^^^^^^^^
  File "/home/airflow/.local/lib/python3.12/site-packages/airflow/models/baseoperator.py", line 422, in wrapper
    return func(self, *args, **kwargs)
           ^^^^^^^^^^^^^^^^^^^^^^^^^^^
  File "/home/airflow/.local/lib/python3.12/site-packages/airflow/providers/docker/operators/docker.py", line 519, in execute
    return self._run_image()
           ^^^^^^^^^^^^^^^^^
  File "/home/airflow/.local/lib/python3.12/site-packages/airflow/providers/docker/operators/docker.py", line 396, in _run_image
    return self._run_image_with_mounts(self.mounts, add_tmp_variable=False)
           ^^^^^^^^^^^^^^^^^^^^^^^^^^^^^^^^^^^^^^^^^^^^^^^^^^^^^^^^^^^^^^^^
  File "/home/airflow/.local/lib/python3.12/site-packages/airflow/providers/docker/operators/docker.py", line 453, in _run_image_with_mounts
    raise DockerContainerFailedException(f"Docker container failed: {result!r}", logs=log_lines)
airflow.providers.docker.exceptions.DockerContainerFailedException: Docker container failed: {'StatusCode': 1}
[2025-02-23T14:07:07.546+0000] {local_task_job_runner.py:266} INFO - Task exited with return code 1
[2025-02-23T14:07:07.555+0000] {taskinstance.py:3895} INFO - 0 downstream tasks scheduled from follow-on schedule check
[2025-02-23T14:07:07.558+0000] {local_task_job_runner.py:245} INFO - ::endgroup::
