[2025-02-22T00:00:04.901+0000] {local_task_job_runner.py:123} INFO - ::group::Pre task execution logs
[2025-02-22T00:00:04.907+0000] {taskinstance.py:2613} INFO - Dependencies all met for dep_context=non-requeueable deps ti=<TaskInstance: etl_climate.extract_data scheduled__2025-02-21T00:00:00+00:00 [queued]>
[2025-02-22T00:00:04.911+0000] {taskinstance.py:2613} INFO - Dependencies all met for dep_context=requeueable deps ti=<TaskInstance: etl_climate.extract_data scheduled__2025-02-21T00:00:00+00:00 [queued]>
[2025-02-22T00:00:04.911+0000] {taskinstance.py:2866} INFO - Starting attempt 1 of 2
[2025-02-22T00:00:04.922+0000] {taskinstance.py:2889} INFO - Executing <Task(DockerOperator): extract_data> on 2025-02-21 00:00:00+00:00
[2025-02-22T00:00:04.929+0000] {standard_task_runner.py:72} INFO - Started process 3788 to run task
[2025-02-22T00:00:04.941+0000] {standard_task_runner.py:104} INFO - Running: ['airflow', 'tasks', 'run', 'etl_climate', 'extract_data', 'scheduled__2025-02-21T00:00:00+00:00', '--job-id', '64', '--raw', '--subdir', 'DAGS_FOLDER/climate_extract_dag.py', '--cfg-path', '/tmp/tmpr9zotndg']
[2025-02-22T00:00:04.944+0000] {standard_task_runner.py:105} INFO - Job 64: Subtask extract_data
[2025-02-22T00:00:05.006+0000] {task_command.py:467} INFO - Running <TaskInstance: etl_climate.extract_data scheduled__2025-02-21T00:00:00+00:00 [running]> on host 470d5c5e78db
[2025-02-22T00:00:05.051+0000] {taskinstance.py:3132} INFO - Exporting env vars: AIRFLOW_CTX_DAG_OWNER='airflow' AIRFLOW_CTX_DAG_ID='etl_climate' AIRFLOW_CTX_TASK_ID='extract_data' AIRFLOW_CTX_EXECUTION_DATE='2025-02-21T00:00:00+00:00' AIRFLOW_CTX_TRY_NUMBER='1' AIRFLOW_CTX_DAG_RUN_ID='scheduled__2025-02-21T00:00:00+00:00'
[2025-02-22T00:00:05.051+0000] {taskinstance.py:731} INFO - ::endgroup::
[2025-02-22T00:00:05.109+0000] {docker.py:379} INFO - Starting docker container from image dbt_docker_image
[2025-02-22T00:00:08.582+0000] {docker.py:73} INFO - [0m00:00:08  Running with dbt=1.9.2
[2025-02-22T00:00:08.860+0000] {docker.py:73} INFO - [0m00:00:08  Registered adapter: duckdb=1.9.1
[2025-02-22T00:00:08.913+0000] {docker.py:73} INFO - [0m00:00:08  Unable to do partial parsing because saved manifest not found. Starting full parse.
[2025-02-22T00:00:10.226+0000] {docker.py:73} INFO - [0m00:00:10  Found 1 model, 1 seed, 19 data tests, 424 macros
[2025-02-22T00:00:10.228+0000] {docker.py:73} INFO - [0m00:00:10
[2025-02-22T00:00:10.228+0000] {docker.py:73} INFO - [0m00:00:10  Concurrency: 1 threads (target='dev')
[2025-02-22T00:00:10.228+0000] {docker.py:73} INFO - [0m00:00:10
[2025-02-22T00:00:12.478+0000] {docker.py:73} INFO - [0m00:00:12  1 of 1 START sql table model main.open_meteo_raw_data .......................... [RUN]
[2025-02-22T00:00:50.098+0000] {docker.py:73} INFO - [0m00:00:50  1 of 1 ERROR creating sql table model main.open_meteo_raw_data ................. [[31mERROR[0m in 37.61s]
[2025-02-22T00:00:50.180+0000] {docker.py:73} INFO - [0m00:00:50
[2025-02-22T00:00:50.180+0000] {docker.py:73} INFO - [0m00:00:50  Finished running 1 table model in 0 hours 0 minutes and 39.95 seconds (39.95s).
[2025-02-22T00:00:50.213+0000] {docker.py:73} INFO - [0m00:00:50
[2025-02-22T00:00:50.213+0000] {docker.py:73} INFO - [0m00:00:50  [31mCompleted with 1 error, 0 partial successes, and 0 warnings:[0m
[2025-02-22T00:00:50.214+0000] {docker.py:73} INFO - [0m00:00:50
[2025-02-22T00:00:50.215+0000] {docker.py:73} INFO - [0m00:00:50    Runtime Error in model open_meteo_raw_data (models/open_meteo_raw_data.sql)
[2025-02-22T00:00:50.215+0000] {docker.py:73} INFO -   TransactionContext Error: Failed to commit: PRIMARY KEY or UNIQUE constraint violation: duplicate key "1970-01-01 00:00:00, 0.0, 0.0"
[2025-02-22T00:00:50.215+0000] {docker.py:73} INFO - [0m00:00:50
[2025-02-22T00:00:50.216+0000] {docker.py:73} INFO - [0m00:00:50  Done. PASS=0 WARN=0 ERROR=1 SKIP=0 TOTAL=1
[2025-02-22T00:00:50.969+0000] {taskinstance.py:3311} ERROR - Task failed with exception
Traceback (most recent call last):
  File "/home/airflow/.local/lib/python3.12/site-packages/airflow/models/taskinstance.py", line 767, in _execute_task
    result = _execute_callable(context=context, **execute_callable_kwargs)
             ^^^^^^^^^^^^^^^^^^^^^^^^^^^^^^^^^^^^^^^^^^^^^^^^^^^^^^^^^^^^^
  File "/home/airflow/.local/lib/python3.12/site-packages/airflow/models/taskinstance.py", line 733, in _execute_callable
    return ExecutionCallableRunner(
           ^^^^^^^^^^^^^^^^^^^^^^^^
  File "/home/airflow/.local/lib/python3.12/site-packages/airflow/utils/operator_helpers.py", line 252, in run
    return self.func(*args, **kwargs)
           ^^^^^^^^^^^^^^^^^^^^^^^^^^
  File "/home/airflow/.local/lib/python3.12/site-packages/airflow/models/baseoperator.py", line 422, in wrapper
    return func(self, *args, **kwargs)
           ^^^^^^^^^^^^^^^^^^^^^^^^^^^
  File "/home/airflow/.local/lib/python3.12/site-packages/airflow/providers/docker/operators/docker.py", line 519, in execute
    return self._run_image()
           ^^^^^^^^^^^^^^^^^
  File "/home/airflow/.local/lib/python3.12/site-packages/airflow/providers/docker/operators/docker.py", line 396, in _run_image
    return self._run_image_with_mounts(self.mounts, add_tmp_variable=False)
           ^^^^^^^^^^^^^^^^^^^^^^^^^^^^^^^^^^^^^^^^^^^^^^^^^^^^^^^^^^^^^^^^
  File "/home/airflow/.local/lib/python3.12/site-packages/airflow/providers/docker/operators/docker.py", line 453, in _run_image_with_mounts
    raise DockerContainerFailedException(f"Docker container failed: {result!r}", logs=log_lines)
airflow.providers.docker.exceptions.DockerContainerFailedException: Docker container failed: {'StatusCode': 1}
[2025-02-22T00:00:50.983+0000] {taskinstance.py:1225} INFO - Marking task as UP_FOR_RETRY. dag_id=etl_climate, task_id=extract_data, run_id=scheduled__2025-02-21T00:00:00+00:00, execution_date=20250221T000000, start_date=20250222T000004, end_date=20250222T000050
[2025-02-22T00:00:50.998+0000] {taskinstance.py:340} INFO - ::group::Post task execution logs
[2025-02-22T00:00:50.998+0000] {standard_task_runner.py:124} ERROR - Failed to execute job 64 for task extract_data (Docker container failed: {'StatusCode': 1}; 3788)
Traceback (most recent call last):
  File "/home/airflow/.local/lib/python3.12/site-packages/airflow/task/task_runner/standard_task_runner.py", line 117, in _start_by_fork
    ret = args.func(args, dag=self.dag)
          ^^^^^^^^^^^^^^^^^^^^^^^^^^^^^
  File "/home/airflow/.local/lib/python3.12/site-packages/airflow/cli/cli_config.py", line 49, in command
    return func(*args, **kwargs)
           ^^^^^^^^^^^^^^^^^^^^^
  File "/home/airflow/.local/lib/python3.12/site-packages/airflow/utils/cli.py", line 116, in wrapper
    return f(*args, **kwargs)
           ^^^^^^^^^^^^^^^^^^
  File "/home/airflow/.local/lib/python3.12/site-packages/airflow/cli/commands/task_command.py", line 483, in task_run
    task_return_code = _run_task_by_selected_method(args, _dag, ti)
                       ^^^^^^^^^^^^^^^^^^^^^^^^^^^^^^^^^^^^^^^^^^^^
  File "/home/airflow/.local/lib/python3.12/site-packages/airflow/cli/commands/task_command.py", line 256, in _run_task_by_selected_method
    return _run_raw_task(args, ti)
           ^^^^^^^^^^^^^^^^^^^^^^^
  File "/home/airflow/.local/lib/python3.12/site-packages/airflow/cli/commands/task_command.py", line 341, in _run_raw_task
    return ti._run_raw_task(
           ^^^^^^^^^^^^^^^^^
  File "/home/airflow/.local/lib/python3.12/site-packages/airflow/utils/session.py", line 97, in wrapper
    return func(*args, session=session, **kwargs)
           ^^^^^^^^^^^^^^^^^^^^^^^^^^^^^^^^^^^^^^
  File "/home/airflow/.local/lib/python3.12/site-packages/airflow/models/taskinstance.py", line 3005, in _run_raw_task
    return _run_raw_task(
           ^^^^^^^^^^^^^^
  File "/home/airflow/.local/lib/python3.12/site-packages/airflow/models/taskinstance.py", line 273, in _run_raw_task
    TaskInstance._execute_task_with_callbacks(
  File "/home/airflow/.local/lib/python3.12/site-packages/airflow/models/taskinstance.py", line 3159, in _execute_task_with_callbacks
    result = self._execute_task(context, task_orig)
             ^^^^^^^^^^^^^^^^^^^^^^^^^^^^^^^^^^^^^^
  File "/home/airflow/.local/lib/python3.12/site-packages/airflow/models/taskinstance.py", line 3183, in _execute_task
    return _execute_task(self, context, task_orig)
           ^^^^^^^^^^^^^^^^^^^^^^^^^^^^^^^^^^^^^^^
  File "/home/airflow/.local/lib/python3.12/site-packages/airflow/models/taskinstance.py", line 767, in _execute_task
    result = _execute_callable(context=context, **execute_callable_kwargs)
             ^^^^^^^^^^^^^^^^^^^^^^^^^^^^^^^^^^^^^^^^^^^^^^^^^^^^^^^^^^^^^
  File "/home/airflow/.local/lib/python3.12/site-packages/airflow/models/taskinstance.py", line 733, in _execute_callable
    return ExecutionCallableRunner(
           ^^^^^^^^^^^^^^^^^^^^^^^^
  File "/home/airflow/.local/lib/python3.12/site-packages/airflow/utils/operator_helpers.py", line 252, in run
    return self.func(*args, **kwargs)
           ^^^^^^^^^^^^^^^^^^^^^^^^^^
  File "/home/airflow/.local/lib/python3.12/site-packages/airflow/models/baseoperator.py", line 422, in wrapper
    return func(self, *args, **kwargs)
           ^^^^^^^^^^^^^^^^^^^^^^^^^^^
  File "/home/airflow/.local/lib/python3.12/site-packages/airflow/providers/docker/operators/docker.py", line 519, in execute
    return self._run_image()
           ^^^^^^^^^^^^^^^^^
  File "/home/airflow/.local/lib/python3.12/site-packages/airflow/providers/docker/operators/docker.py", line 396, in _run_image
    return self._run_image_with_mounts(self.mounts, add_tmp_variable=False)
           ^^^^^^^^^^^^^^^^^^^^^^^^^^^^^^^^^^^^^^^^^^^^^^^^^^^^^^^^^^^^^^^^
  File "/home/airflow/.local/lib/python3.12/site-packages/airflow/providers/docker/operators/docker.py", line 453, in _run_image_with_mounts
    raise DockerContainerFailedException(f"Docker container failed: {result!r}", logs=log_lines)
airflow.providers.docker.exceptions.DockerContainerFailedException: Docker container failed: {'StatusCode': 1}
[2025-02-22T00:00:51.031+0000] {local_task_job_runner.py:266} INFO - Task exited with return code 1
[2025-02-22T00:00:51.046+0000] {taskinstance.py:3895} INFO - 0 downstream tasks scheduled from follow-on schedule check
[2025-02-22T00:00:51.047+0000] {local_task_job_runner.py:245} INFO - ::endgroup::
