[2025-02-18T02:21:54.497+0000] {local_task_job_runner.py:123} INFO - ::group::Pre task execution logs
[2025-02-18T02:21:54.504+0000] {taskinstance.py:2613} INFO - Dependencies all met for dep_context=non-requeueable deps ti=<TaskInstance: etl_climate.build_evidence_project manual__2025-02-18T02:21:09.898007+00:00 [queued]>
[2025-02-18T02:21:54.507+0000] {taskinstance.py:2613} INFO - Dependencies all met for dep_context=requeueable deps ti=<TaskInstance: etl_climate.build_evidence_project manual__2025-02-18T02:21:09.898007+00:00 [queued]>
[2025-02-18T02:21:54.507+0000] {taskinstance.py:2866} INFO - Starting attempt 1 of 1
[2025-02-18T02:21:54.516+0000] {taskinstance.py:2889} INFO - Executing <Task(BashOperator): build_evidence_project> on 2025-02-18 02:21:09.898007+00:00
[2025-02-18T02:21:54.520+0000] {standard_task_runner.py:72} INFO - Started process 357 to run task
[2025-02-18T02:21:54.522+0000] {standard_task_runner.py:104} INFO - Running: ['airflow', 'tasks', 'run', 'etl_climate', 'build_evidence_project', 'manual__2025-02-18T02:21:09.898007+00:00', '--job-id', '34', '--raw', '--subdir', 'DAGS_FOLDER/climate_extract_dag.py', '--cfg-path', '/tmp/tmp7fh49yde']
[2025-02-18T02:21:54.523+0000] {standard_task_runner.py:105} INFO - Job 34: Subtask build_evidence_project
[2025-02-18T02:21:54.542+0000] {task_command.py:467} INFO - Running <TaskInstance: etl_climate.build_evidence_project manual__2025-02-18T02:21:09.898007+00:00 [running]> on host f1d396ca8f61
[2025-02-18T02:21:54.576+0000] {taskinstance.py:3132} INFO - Exporting env vars: AIRFLOW_CTX_DAG_OWNER='airflow' AIRFLOW_CTX_DAG_ID='etl_climate' AIRFLOW_CTX_TASK_ID='build_evidence_project' AIRFLOW_CTX_EXECUTION_DATE='2025-02-18T02:21:09.898007+00:00' AIRFLOW_CTX_TRY_NUMBER='1' AIRFLOW_CTX_DAG_RUN_ID='manual__2025-02-18T02:21:09.898007+00:00'
[2025-02-18T02:21:54.577+0000] {taskinstance.py:731} INFO - ::endgroup::
[2025-02-18T02:21:54.586+0000] {subprocess.py:78} INFO - Tmp dir root location: /tmp
[2025-02-18T02:21:54.586+0000] {subprocess.py:88} INFO - Running command: ['/usr/bin/bash', '-c', 'cd /opt/evidence_UI; npm run build && aws s3 sync ./build s3://liaoyunfei.name;']
[2025-02-18T02:21:54.592+0000] {subprocess.py:99} INFO - Output:
[2025-02-18T02:21:55.078+0000] {subprocess.py:106} INFO - 
[2025-02-18T02:21:55.078+0000] {subprocess.py:106} INFO - > my-evidence-project@0.0.1 build
[2025-02-18T02:21:55.078+0000] {subprocess.py:106} INFO - > evidence build
[2025-02-18T02:21:55.079+0000] {subprocess.py:106} INFO - 
[2025-02-18T02:21:55.085+0000] {subprocess.py:106} INFO - sh: 1: evidence: Permission denied
[2025-02-18T02:21:55.090+0000] {subprocess.py:110} INFO - Command exited with return code 127
[2025-02-18T02:21:55.095+0000] {taskinstance.py:3311} ERROR - Task failed with exception
Traceback (most recent call last):
  File "/home/airflow/.local/lib/python3.12/site-packages/airflow/models/taskinstance.py", line 767, in _execute_task
    result = _execute_callable(context=context, **execute_callable_kwargs)
             ^^^^^^^^^^^^^^^^^^^^^^^^^^^^^^^^^^^^^^^^^^^^^^^^^^^^^^^^^^^^^
  File "/home/airflow/.local/lib/python3.12/site-packages/airflow/models/taskinstance.py", line 733, in _execute_callable
    return ExecutionCallableRunner(
           ^^^^^^^^^^^^^^^^^^^^^^^^
  File "/home/airflow/.local/lib/python3.12/site-packages/airflow/utils/operator_helpers.py", line 252, in run
    return self.func(*args, **kwargs)
           ^^^^^^^^^^^^^^^^^^^^^^^^^^
  File "/home/airflow/.local/lib/python3.12/site-packages/airflow/models/baseoperator.py", line 422, in wrapper
    return func(self, *args, **kwargs)
           ^^^^^^^^^^^^^^^^^^^^^^^^^^^
  File "/home/airflow/.local/lib/python3.12/site-packages/airflow/operators/bash.py", line 276, in execute
    raise AirflowException(
airflow.exceptions.AirflowException: Bash command failed. The command returned a non-zero exit code 127.
[2025-02-18T02:21:55.098+0000] {taskinstance.py:1225} INFO - Marking task as FAILED. dag_id=etl_climate, task_id=build_evidence_project, run_id=manual__2025-02-18T02:21:09.898007+00:00, execution_date=20250218T022109, start_date=20250218T022154, end_date=20250218T022155
[2025-02-18T02:21:55.105+0000] {taskinstance.py:340} INFO - ::group::Post task execution logs
[2025-02-18T02:21:55.105+0000] {standard_task_runner.py:124} ERROR - Failed to execute job 34 for task build_evidence_project (Bash command failed. The command returned a non-zero exit code 127.; 357)
Traceback (most recent call last):
  File "/home/airflow/.local/lib/python3.12/site-packages/airflow/task/task_runner/standard_task_runner.py", line 117, in _start_by_fork
    ret = args.func(args, dag=self.dag)
          ^^^^^^^^^^^^^^^^^^^^^^^^^^^^^
  File "/home/airflow/.local/lib/python3.12/site-packages/airflow/cli/cli_config.py", line 49, in command
    return func(*args, **kwargs)
           ^^^^^^^^^^^^^^^^^^^^^
  File "/home/airflow/.local/lib/python3.12/site-packages/airflow/utils/cli.py", line 116, in wrapper
    return f(*args, **kwargs)
           ^^^^^^^^^^^^^^^^^^
  File "/home/airflow/.local/lib/python3.12/site-packages/airflow/cli/commands/task_command.py", line 483, in task_run
    task_return_code = _run_task_by_selected_method(args, _dag, ti)
                       ^^^^^^^^^^^^^^^^^^^^^^^^^^^^^^^^^^^^^^^^^^^^
  File "/home/airflow/.local/lib/python3.12/site-packages/airflow/cli/commands/task_command.py", line 256, in _run_task_by_selected_method
    return _run_raw_task(args, ti)
           ^^^^^^^^^^^^^^^^^^^^^^^
  File "/home/airflow/.local/lib/python3.12/site-packages/airflow/cli/commands/task_command.py", line 341, in _run_raw_task
    return ti._run_raw_task(
           ^^^^^^^^^^^^^^^^^
  File "/home/airflow/.local/lib/python3.12/site-packages/airflow/utils/session.py", line 97, in wrapper
    return func(*args, session=session, **kwargs)
           ^^^^^^^^^^^^^^^^^^^^^^^^^^^^^^^^^^^^^^
  File "/home/airflow/.local/lib/python3.12/site-packages/airflow/models/taskinstance.py", line 3005, in _run_raw_task
    return _run_raw_task(
           ^^^^^^^^^^^^^^
  File "/home/airflow/.local/lib/python3.12/site-packages/airflow/models/taskinstance.py", line 273, in _run_raw_task
    TaskInstance._execute_task_with_callbacks(
  File "/home/airflow/.local/lib/python3.12/site-packages/airflow/models/taskinstance.py", line 3159, in _execute_task_with_callbacks
    result = self._execute_task(context, task_orig)
             ^^^^^^^^^^^^^^^^^^^^^^^^^^^^^^^^^^^^^^
  File "/home/airflow/.local/lib/python3.12/site-packages/airflow/models/taskinstance.py", line 3183, in _execute_task
    return _execute_task(self, context, task_orig)
           ^^^^^^^^^^^^^^^^^^^^^^^^^^^^^^^^^^^^^^^
  File "/home/airflow/.local/lib/python3.12/site-packages/airflow/models/taskinstance.py", line 767, in _execute_task
    result = _execute_callable(context=context, **execute_callable_kwargs)
             ^^^^^^^^^^^^^^^^^^^^^^^^^^^^^^^^^^^^^^^^^^^^^^^^^^^^^^^^^^^^^
  File "/home/airflow/.local/lib/python3.12/site-packages/airflow/models/taskinstance.py", line 733, in _execute_callable
    return ExecutionCallableRunner(
           ^^^^^^^^^^^^^^^^^^^^^^^^
  File "/home/airflow/.local/lib/python3.12/site-packages/airflow/utils/operator_helpers.py", line 252, in run
    return self.func(*args, **kwargs)
           ^^^^^^^^^^^^^^^^^^^^^^^^^^
  File "/home/airflow/.local/lib/python3.12/site-packages/airflow/models/baseoperator.py", line 422, in wrapper
    return func(self, *args, **kwargs)
           ^^^^^^^^^^^^^^^^^^^^^^^^^^^
  File "/home/airflow/.local/lib/python3.12/site-packages/airflow/operators/bash.py", line 276, in execute
    raise AirflowException(
airflow.exceptions.AirflowException: Bash command failed. The command returned a non-zero exit code 127.
[2025-02-18T02:21:55.116+0000] {local_task_job_runner.py:266} INFO - Task exited with return code 1
[2025-02-18T02:21:55.123+0000] {taskinstance.py:3895} INFO - 0 downstream tasks scheduled from follow-on schedule check
[2025-02-18T02:21:55.123+0000] {local_task_job_runner.py:245} INFO - ::endgroup::
